Workbook

Sheet TV Series Dataset
A1: Viewer ID | B1: Age | C1: Gender | D1: Country | E1: Favorite TV Series | F1: Genre | G1: Episodes Watched Per Session | H1: Hours Watched Per Week | I1: Preferred Watching Time | J1: Viewing Day Type | K1: Series Rating | L1: Age Category | M1: Viewer Type | N1: Engagement Level
A2: V001 | B2: 39 | C2: Female | D2: Australia | E2: The Office | F2: Comedy | G2: 3 | H2: 12 | I2: Night | J2: Weekend | K2: 9 | L2: =IF(B2<=25,"18-25",IF(B2<=35,"26-35",IF(B2<=45,"36-45","46+"))) -> 36-45 | M2: =IF(G2<=2,"Casual Viewer",IF(G2<=4,"Regular Viewer","Binge Watcher")) -> Regular Viewer | N2: =IF(H2<=5,"Low",IF(H2<=10,"Medium","High")) -> High
A3: V002 | B3: 18 | C3: Female | D3: Germany | E3: Lost | F3: Mystery/Drama | G3: 5 | H3: 2 | I3: Night | J3: Weekend | K3: 9 | L3: =IF(B3<=25,"18-25",IF(B3<=35,"26-35",IF(B3<=45,"36-45","46+"))) -> 18-25 | M3: =IF(G3<=2,"Casual Viewer",IF(G3<=4,"Regular Viewer","Binge Watcher")) -> Binge Watcher | N3: =IF(H3<=5,"Low",IF(H3<=10,"Medium","High")) -> Low
A4: V003 | B4: 20 | C4: Male | D4: Germany | E4: Narcos | F4: Crime | G4: 3 | H4: 1 | I4: Night | J4: Weekend | K4: 10 | L4: =IF(B4<=25,"18-25",IF(B4<=35,"26-35",IF(B4<=45,"36-45","46+"))) -> 18-25 | M4: =IF(G4<=2,"Casual Viewer",IF(G4<=4,"Regular Viewer","Binge Watcher")) -> Regular Viewer | N4: =IF(H4<=5,"Low",IF(H4<=10,"Medium","High")) -> Low
A5: V004 | B5: 27 | C5: Male | D5: India | E5: Prison Break | F5: Crime/Drama | G5: 5 | H5: 9 | I5: Afternoon | J5: Weekday | K5: 8 | L5: =IF(B5<=25,"18-25",IF(B5<=35,"26-35",IF(B5<=45,"36-45","46+"))) -> 26-35 | M5: =IF(G5<=2,"Casual Viewer",IF(G5<=4,"Regular Viewer","Binge Watcher")) -> Binge Watcher | N5: =IF(H5<=5,"Low",IF(H5<=10,"Medium","High")) -> Medium
A6: V005 | B6: 24 | C6: Female | D6: USA | E6: Wednesday | F6: Mystery/Comedy | G6: 1 | H6: 9 | I6: Afternoon | J6: Weekday | K6: 10 | L6: =IF(B6<=25,"18-25",IF(B6<=35,"26-35",IF(B6<=45,"36-45","46+"))) -> 18-25 | M6: =IF(G6<=2,"Casual Viewer",IF(G6<=4,"Regular Viewer","Binge Watcher")) -> Casual Viewer | N6: =IF(H6<=5,"Low",IF(H6<=10,"Medium","High")) -> Medium
A7: V006 | B7: 22 | C7: Male | D7: Japan | E7: Wednesday | F7: Mystery/Comedy | G7: 3 | H7: 12 | I7: Night | J7: Weekend | K7: 9 | L7: =IF(B7<=25,"18-25",IF(B7<=35,"26-35",IF(B7<=45,"36-45","46+"))) -> 18-25 | M7: =IF(G7<=2,"Casual Viewer",IF(G7<=4,"Regular Viewer","Binge Watcher")) -> Regular Viewer | N7: =IF(H7<=5,"Low",IF(H7<=10,"Medium","High")) -> High
A8: V007 | B8: 37 | C8: Male | D8: Canada | E8: Narcos | F8: Crime | G8: 4 | H8: 13 | I8: Afternoon | J8: Weekend | K8: 7 | L8: =IF(B8<=25,"18-25",IF(B8<=35,"26-35",IF(B8<=45,"36-45","46+"))) -> 36-45 | M8: =IF(G8<=2,"Casual Viewer",IF(G8<=4,"Regular Viewer","Binge Watcher")) -> Regular Viewer | N8: =IF(H8<=5,"Low",IF(H8<=10,"Medium","High")) -> High
A9: V008 | B9: 21 | C9: Female | D9: France | E9: Breaking Bad | F9: Crime/Drama | G9: 1 | H9: 9 | I9: Night | J9: Weekday | K9: 8 | L9: =IF(B9<=25,"18-25",IF(B9<=35,"26-35",IF(B9<=45,"36-45","46+"))) -> 18-25 | M9: =IF(G9<=2,"Casual Viewer",IF(G9<=4,"Regular Viewer","Binge Watcher")) -> Casual Viewer | N9: =IF(H9<=5,"Low",IF(H9<=10,"Medium","High")) -> Medium
A10: V009 | B10: 19 | C10: Male | D10: Germany | E10: Peaky Blinders | F10: Crime/Drama | G10: 1 | H10: 10 | I10: Night | J10: Weekend | K10: 8 | L10: =IF(B10<=25,"18-25",IF(B10<=35,"26-35",IF(B10<=45,"36-45","46+"))) -> 18-25 | M10: =IF(G10<=2,"Casual Viewer",IF(G10<=4,"Regular Viewer","Binge Watcher")) -> Casual Viewer | N10: =IF(H10<=5,"Low",IF(H10<=10,"Medium","High")) -> Medium
A11: V010 | B11: 32 | C11: Female | D11: Brazil | E11: The Office | F11: Comedy | G11: 3 | H11: 7 | I11: Night | J11: Weekday | K11: 9 | L11: =IF(B11<=25,"18-25",IF(B11<=35,"26-35",IF(B11<=45,"36-45","46+"))) -> 26-35 | M11: =IF(G11<=2,"Casual Viewer",IF(G11<=4,"Regular Viewer","Binge Watcher")) -> Regular Viewer | N11: =IF(H11<=5,"Low",IF(H11<=10,"Medium","High")) -> Medium
A12: V011 | B12: 19 | C12: Male | D12: Australia | E12: The Mandalorian | F12: Sci-Fi | G12: 5 | H12: 5 | I12: Night | J12: Weekday | K12: 10 | L12: =IF(B12<=25,"18-25",IF(B12<=35,"26-35",IF(B12<=45,"36-45","46+"))) -> 18-25 | M12: =IF(G12<=2,"Casual Viewer",IF(G12<=4,"Regular Viewer","Binge Watcher")) -> Binge Watcher | N12: =IF(H12<=5,"Low",IF(H12<=10,"Medium","High")) -> Low
A13: V012 | B13: 23 | C13: Female | D13: USA | E13: House of the Dragon | F13: Fantasy | G13: 7 | H13: 11 | I13: Night | J13: Weekend | K13: 8 | L13: =IF(B13<=25,"18-25",IF(B13<=35,"26-35",IF(B13<=45,"36-45","46+"))) -> 18-25 | M13: =IF(G13<=2,"Casual Viewer",IF(G13<=4,"Regular Viewer","Binge Watcher")) -> Binge Watcher | N13: =IF(H13<=5,"Low",IF(H13<=10,"Medium","High")) -> High
... A301: V300 | B301: 20 | C301: Female | D301: USA | E301: Peaky Blinders | F301: Crime/Drama | G301: 4 | H301: 1 | I301: Morning | J301: Weekend | K301: 5 | L301: =IF(B301<=25,"18-25",IF(B301<=35,"26-35",IF(B301<=45,"36-45","46+"))) -> 18-25 | M301: =IF(G301<=2,"Casual Viewer",IF(G301<=4,"Regular Viewer","Binge Watcher")) -> Regular Viewer | N301: =IF(H301<=5,"Low",IF(H301<=10,"Medium","High")) -> Low

Sheet Sheet1
A1: Row Labels | B1: Count of Viewer ID
A2: Stranger Things | B2: 20 | P2: Row Labels | Q2: Count of Viewer ID
A3: The Mandalorian | B3: 18 | P3: Sci-Fi | Q3: 74
A4: Narcos | B4: 15 | P4: Comedy | Q4: 53
A5: Wednesday | B5: 15 | P5: Crime/Drama | Q5: 51
A6: How I Met Your Mother | B6: 15 | P6: Fantasy | Q6: 33
A7: Loki | B7: 14 | P7: Mystery/Comedy | Q7: 15
A8: The Office | B8: 14 | P8: Crime | Q8: 15
A9: Lost | B9: 14 | P9: Mystery/Drama | Q9: 14
A10: Modern Family | B10: 14 | P10: Action/Sci-Fi | Q10: 13
A11: House of the Dragon | B11: 13 | P11: Crime/Thriller | Q11: 13
A12: The Boys | B12: 13 | P12: Thriller | Q12: 7
A13: Money Heist | B13: 13 | P13: Historical/Drama | Q13: 6
A14: Peaky Blinders | B14: 12 | P14: Crime/Mystery | Q14: 6
A15: Dark | B15: 11 | P15: Grand Total | Q15: 300
A16: Breaking Bad | B16: 11
A17: Better Call Saul | B17: 11
A18: The Witcher | B18: 11
A19: Black Mirror | B19: 11
A20: Friends | B20: 10
A21: Prison Break | B21: 9
A22: Game of Thrones | B22: 9
A23: True Detective | B23: 8
A24: Squid Game | B24: 7
A25: Vikings | B25: 6
A26: Sherlock | B26: 6
A27: Grand Total | B27: 300
D33: Count of Viewer ID | E33: Column Labels | L33: Row Labels | M33: Count of Viewer ID
D34: Row Labels | E34: 18-25 | F34: 26-35 | G34: 36-45 | H34: 46+ | I34: Grand Total | L34: Casual Viewer | M34: 123
D35: Crime/Drama | E35: 32 | F35: 12 | G35: 3 | H35: 4 | I35: 51 | L35: Regular Viewer | M35: 117
D36: Comedy | E36: 26 | F36: 19 | G36: 5 | H36: 3 | I36: 53 | L36: Binge Watcher | M36: 60
D37: Sci-Fi | E37: 46 | F37: 15 | G37: 10 | H37: 3 | I37: 74 | L37: Grand Total | M37: 300
D38: Fantasy | E38: 19 | F38: 9 | G38: 3 | H38: 2 | I38: 33
D39: Crime | E39: 10 | F39: 2 | G39: 2 | H39: 1 | I39: 15
D40: Mystery/Comedy | E40: 10 | F40: 2 | G40: 3 | I40: 15
D41: Historical/Drama | E41: 3 | F41: 2 | G41: 1 | I41: 6
D42: Mystery/Drama | E42: 11 | F42: 2 | G42: 1 | I42: 14
D43: Thriller | E43: 5 | F43: 1 | G43: 1 | I43: 7
D44: Crime/Mystery | E44: 4 | F44: 2 | I44: 6
D45: Action/Sci-Fi | E45: 9 | F45: 4 | I45: 13
...

Sheet Sheet2
A1: Row Labels | B1: Count of Viewer ID | K1: Row Labels | L1: Average of Series Rating
A2: Night | B2: 140 | K2: Fantasy | L2: 9.1212121
A3: Afternoon | B3: 90 | K3: Sci-Fi | L3: 8.9594595
A4: Morning | B4: 70 | K4: Comedy | L4: 8.3396226
A5: Grand Total | B5: 300 | K5: Mystery/Comedy | L5: 7.8666667
K6: Crime | L6: 6.6666667
K7: Crime/Drama | L7: 6.5882353
K8: Crime/Thriller | L8: 6.5384615
K9: Action/Sci-Fi | L9: 6.1538462
K10: Mystery/Drama | L10: 6.0714286
K11: Historical/Drama | L11: 6
K12: Thriller | L12: 5.1428571
K13: Crime/Mystery | L13: 4.5
K14: Grand Total | L14: 7.6966667

Sheet Sheet3
B1: Hours Watched per weak | F1: Hours Watched per week | K1: Episodes Watched Per Session | N1: Episodes Watched Per Session
B2: Morning | C2: Afternoon | D2: Night | F2: Morning | G2: Afternoon | H2: Night | K2: Weekday | L2: Weekend | N2: Weekday | O2: Weekend
A3: Mean | B3: =AVERAGE(F3:F72) -> 7.3 | C3: =AVERAGE(G3:G92) -> 8.2333333 | D3: =AVERAGE(H3:H142) -> 7.5928571 | F3: 11 | G3: 9 | H3: 12 | J3: Mean | K3: =AVERAGE(N3:N164) -> 2.9444444 | L3: =AVERAGE(O3:O140) -> 3.0072464 | N3: 5 | O3: 3
A4: Median | B4: =MEDIAN(F3:F72 ) -> 7 | C4: =MEDIAN(G3:G92) -> 9 | D4: =MEDIAN(H3:H142) -> 8 | F4: 13 | G4: 9 | H4: 2 | J4: Median | K4: =MEDIAN(N3:N164) -> 3 | L4: =MEDIAN(O3:O140) -> 3 | N4: 1 | O4: 5
A5: Mode | B5: =MODE(F3:F72) -> 3 | C5: =MODE(G3:G92) -> 10 | D5: =MODE(H3:H142) -> 12 | F5: 12 | G5: 13 | H5: 1 | J5: Mode | K5: =MODE(N3:N164) -> 1 | L5: =MODE(O3:O140) -> 3 | N5: 1 | O5: 3
A6: Skewness | B6: =SKEW(F3:F72) -> 0.12358802 | C6: =SKEW(G3:G92) -> -0.10436044 | D6: =SKEW(H3:H142) -> 0.059431266 | F6: 13 | G6: 10 | H6: 12 | J6: Skewness | K6: =SKEW(N3:N164) -> 0.30051347 | L6: =SKEW(O3:O140) -> 0.10210353 | N6: 3 | O6: 3
A7: Comparision | B7: The afternoon viewing period shows slightly higher average watching behavior compared to morning and night, while morning and night remain relatively similar, and the distribution across all three time periods appears fairly balanced with only minor skewness indicating slight variations in viewing patterns. | F7: 5 | G7: 6 | H7: 9 | J7: Comparision | K7: The number of episodes watched per session is quite similar on weekdays and weekends, with viewers generally watching about the same amount, while the weekday data shows slightly more variation and the weekend viewing pattern appears more consistent with only mild positive skewness. | N7: 5 | O7: 4
F8: 14 | G8: 8 | H8: 10 | N8: 2 | O8: 1
F9: 6 | G9: 9 | H9: 7 | N9: 5 | O9: 7
F10: 3 | G10: 13 | H10: 5 | N10: 2 | O10: 5
F11: 3 | G11: 6 | H11: 11 | N11: 3 | O11: 2
F12: 5 | G12: 1 | H12: 8 | N12: 1 | O12: 5
F13: 3 | G13: 14 | H13: 3 | N13: 1 | O13: 3
F14: 2 | G14: 14 | H14: 13 | N14: 3 | O14: 1
F15: 12 | G15: 4 | H15: 2 | N15: 1 | O15: 4
F16: 3 | G16: 14 | H16: 10 | N16: 1 | O16: 5
F17: 5 | G17: 12 | H17: 11 | N17: 2 | O17: 3
F18: 14 | G18: 6 | H18: 2 | N18: 5 | O18: 2
F19: 5 | G19: 6 | H19: 9 | N19: 2 | O19: 5
... F72: 1 | G72: 3 | H72: 2 | N72: 4 | O72: 5
G73: 8 | H73: 12 | N73: 1 | O73: 4
G74: 1 | H74: 5 | N74: 3 | O74: 1
G75: 15 | H75: 1 | N75: 3 | O75: 1
G76: 10 | H76: 3 | N76: 5 | O76: 1
G77: 2 | H77: 4 | N77: 5 | O77: 5
G78: 1 | H78: 4 | N78: 2 | O78: 2
G79: 10 | H79: 8 | N79: 2 | O79: 1
G80: 10 | H80: 6 | N80: 1 | O80: 2
G81: 7 | H81: 14 | N81: 3 | O81: 5
G82: 12 | H82: 1 | N82: 1 | O82: 4
G83: 2 | H83: 12 | N83: 4 | O83: 1
G84: 12 | H84: 5 | N84: 4 | O84: 2
... G92: 1 | H92: 13 | N92: 5 | O92: 4
H93: 3 | N93: 5 | O93: 3
H94: 10 | N94: 4 | O94: 2
H95: 12 | N95: 2 | O95: 4
H96: 13 | N96: 2 | O96: 4
H97: 12 | N97: 2 | O97: 1
H98: 12 | N98: 3 | O98: 3
H99: 1 | N99: 3 | O99: 4
...

Sheet Sheet4
B1: Age Category | G1: Age Category
A2: Measures of Spread | B2: 18-25 | C2: 26-35 | D2: 36-45 | E2: 45+ | G2: 18-25 | H2: 26-35 | I2: 36-45 | J2: 45+
A3: Range | B3: =MAX(G:G)-MIN(G:G) -> 9 | C3: =MAX(H:H)-MIN(H:H) -> 9 | D3: =MAX(I:I)-MIN(I:I) -> 8 | E3: =MAX(J:J)-MIN(J:J) -> 8 | G3: 9 | H3: 8 | I3: 9 | J3: 2
A4: Variance | B4: =_xlfn.VAR.S(G:G) -> 6.0670391 | C4: =_xlfn.VAR.S(H:H) -> 6.747027 | D4: =_xlfn.VAR.S(I:I) -> 4.9909274 | E4: =_xlfn.VAR.S(J:J) -> 5.7692308 | G4: 10 | H4: 9 | I4: 7 | J4: 9
A5: Standard Deviation | B5: =_xlfn.STDEV.S(G:G) -> 2.463136 | C5: =_xlfn.STDEV.S(H:H) -> 2.597504 | D5: =STDEV(I:I) -> 2.2340384 | E5: =_xlfn.STDEV.S(J:J) -> 2.4019223 | G5: 10 | H5: 10 | I5: 10 | J5: 6
G6: 9 | H6: 10 | I6: 8 | J6: 5
G7: 8 | H7: 9 | I7: 9 | J7: 9
G8: 8 | H8: 9 | I8: 10 | J8: 9
G9: 10 | H9: 8 | I9: 9 | J9: 6
G10: 8 | H10: 7 | I10: 8 | J10: 5
G11: 9 | H11: 6 | I11: 10 | J11: 9
G12: 10 | H12: 9 | I12: 10 | J12: 9
G13: 9 | H13: 9 | I13: 10 | J13: 9
G14: 10 | H14: 9 | I14: 6 | J14: 9
G15: 10 | H15: 8 | I15: 9 | J15: 10
G16: 9 | H16: 9 | I16: 8
G17: 10 | H17: 8 | I17: 10
G18: 9 | H18: 8 | I18: 10
G19: 9 | H19: 9 | I19: 4
G20: 9 | H20: 10 | I20: 6
G21: 10 | H21: 9 | I21: 9
G22: 9 | H22: 9 | I22: 5
G23: 8 | H23: 9 | I23: 9
G24: 4 | H24: 10 | I24: 9
G25: 7 | H25: 9 | I25: 2
G26: 5 | H26: 4 | I26: 2
G27: 4 | H27: 9 | I27: 9
... G34: 9 | H34: 4 | I34: 7
G35: 1 | H35: 9
G36: 8 | H36: 10
G37: 9 | H37: 7
G38: 10 | H38: 10
G39: 6 | H39: 1
G40: 9 | H40: 4
G41: 3 | H41: 9
G42: 9 | H42: 9
G43: 9 | H43: 9
G44: 9 | H44: 8
G45: 9 | H45: 9
G46: 8 | H46: 10
...

Sheet Sheet5
A1: Average Series Rating | B1: Average hours watched per week | C1: Average Episodes Watched per session | D1: Maximum hours watched per week | E1: Maximum Episodes Watched per session
A2: =AVERAGE('TV Series Dataset'!K2:K301) -> 7.6966667 | B2: =AVERAGE('TV Series Dataset'!H2:H301) -> 7.7166667 | C2: =AVERAGE('TV Series Dataset'!G2:G301) -> 2.9733333 | D2: =MAX('TV Series Dataset'!H2:H301) -> 15 | E2: =MAX('TV Series Dataset'!G2:G301) -> 8
A4: Binge Watching rate(%) | B4: Night Viewing Share(%) | C4: Hight Engagement Rate(%) | D4: Low Enagagement Rate(%) | E4: Favourite Genre percentage(Sci-Fi)%
A5: =COUNTIF('TV Series Dataset'!M:M,"Binge Watcher")/COUNTA('TV Series Dataset'!M:M)*100 -> 19.933555 | B5: =COUNTIF('TV Series Dataset'!I:I,"Night")/COUNTA('TV Series Dataset'!I:I)*100 -> 46.511628 | C5: =COUNTIF('TV Series Dataset'!N:N,"High")/COUNTA('TV Series Dataset'!N:N)*100 -> 28.571429 | D5: =COUNTIF('TV Series Dataset'!N:N,"Low")/COUNTA('TV Series Dataset'!N:N)*100 -> 36.212625 | E5: =COUNTIF('TV Series Dataset'!F:F,"Sci-Fi")/COUNTA('TV Series Dataset'!F:F)*100 -> 24.584718
A7: Row Labels | B7: Count of Viewer ID | F7: Row Labels | G7: Count of Viewer ID
A8: 18-25 | B8: 180 | F8: Low | G8: 109
A9: 26-35 | B9: 75 | F9: Medium | G9: 105
A10: 36-45 | B10: 32 | F10: High | G10: 86
A11: 46+ | B11: 13 | F11: Grand Total | G11: 300
A12: Grand Total | B12: 300
A24: Row Labels | B24: Count of Viewer ID | F24: Row Labels | G24: Count of Viewer ID
A25: Female | B25: 139 | F25: Afternoon | G25: 90
A26: Male | B26: 161 | F26: Morning | G26: 70
A27: Grand Total | B27: 300 | F27: Night | G27: 140
F28: Grand Total | G28: 300

Sheet Dashboard
J1: TV Series Viewing Behavior Analysis
B3: Total Viewers = 300 | F3: Most Popular Series = Stranger Things | K3: Most Popular Genre = Sci-Fi | P3: Most Preferred Watching Time = Night | U3: Largest Viewer Age Group = 18 - 25 | Z3: Primary Viewer Type = Casual Viewer
